Workbook

Sheet Pay Scale
A1: Firefighter Pay Scale — Updated with the Act 111 Award Raises
A2: Rebuild of the GM# 23-73 step sheet with the 2025–2027 Act 111 Award raises layered in (+3% 07/01/2025, +1% 01/01/2026, +3% 07/01/2026, compounded) and the award longevity schedule. Every figure is a live formula — change a blue or yellow cell and the whole sheet recalculates.
A3: Blue = typed input · Yellow = check this against your own record · Black = calculated
A4: Effective Date | B4: 45022 | C4: 45297 | D4: 45474 | E4: 45753 | F4: 45839 | G4: 46023 | H4: 46118 | I4: 46204 | J4: 46483 | K4: 46849
A5: What Changes | B5: Step 1 | C5: Step 2 | D5: 5% Raise | E5: Step 3 | F5: Award +3% | G5: Award +1% | H5: Step 4 | I5: Award +3% | J5: Step 5 | K5: Step 6
A6: Scale Salary from GM# 23-73 (before award) | B6: 61888 | C6: 66183 | D6: 69492.15 | E6: 75814.2 | F6: 75814.2 | G6: 75814.2 | H6: 81226.95 | I6: 81226.95 | J6: 86642.85 | K6: 90252.75
A7: Award Raise Factor (compounded) | B7: =IF(B$4>=$B$35,1+$C$35,1)*IF(B$4>=$B$36,1+$C$36,1)*IF(B$4>=$B$37,1+$C$37,1) | C7: =IF(C$4>=$B$35,1+$C$35,1)*IF(C$4>=$B$36,1+$C$36,1)*IF(C$4>=$B$37,1+$C$37,1) | D7: =IF(D$4>=$B$35,1+$C$35,1)*IF(D$4>=$B$36,1+$C$36,1)*IF(D$4>=$B$37,1+$C$37,1) | E7: =IF(E$4>=$B$35,1+$C$35,1)*IF(E$4>=$B$36,1+$C$36,1)*IF(E$4>=$B$37,1+$C$37,1) | F7: =IF(F$4>=$B$35,1+$C$35,1)*IF(F$4>=$B$36,1+$C$36,1)*IF(F$4>=$B$37,1+$C$37,1) | G7: =IF(G$4>=$B$35,1+$C$35,1)*IF(G$4>=$B$36,1+$C$36,1)*IF(G$4>=$B$37,1+$C$37,1) | H7: =IF(H$4>=$B$35,1+$C$35,1)*IF(H$4>=$B$36,1+$C$36,1)*IF(H$4>=$B$37,1+$C$37,1) | I7: =IF(I$4>=$B$35,1+$C$35,1)*IF(I$4>=$B$36,1+$C$36,1)*IF(I$4>=$B$37,1+$C$37,1) | ... K7: =IF(K$4>=$B$35,1+$C$35,1)*IF(K$4>=$B$36,1+$C$36,1)*IF(K$4>=$B$37,1+$C$37,1)
A8: Salary WITH Award Raises | B8: =B6*B7 | C8: =C6*C7 | D8: =D6*D7 | E8: =E6*E7 | F8: =F6*F7 | G8: =G6*G7 | H8: =H6*H7 | I8: =I6*I7 | ... K8: =K6*K7
A9: Hourly Rate (Divide by 2192) | B9: =B8/$B$26 | C9: =C8/$B$26 | D9: =D8/$B$26 | E9: =E8/$B$26 | F9: =F8/$B$26 | G9: =G8/$B$26 | H9: =H8/$B$26 | I9: =I8/$B$26 | ... K9: =K8/$B$26
A10: Bi-Weekly Base Pay (84 hrs) | B10: =B9*$B$27 | C10: =C9*$B$27 | D10: =D9*$B$27 | E10: =E9*$B$27 | F10: =F9*$B$27 | G10: =G9*$B$27 | H10: =H9*$B$27 | I10: =I9*$B$27 | ... K10: =K9*$B$27
A11: Premium/OT Hourly (Divide by 2088) | B11: =B8/$B$29 | C11: =C8/$B$29 | D11: =D8/$B$29 | E11: =E8/$B$29 | F11: =F8/$B$29 | G11: =G8/$B$29 | H11: =H8/$B$29 | I11: =I8/$B$29 | ... K11: =K8/$B$29
A12: Bi-Weekly Premium Pay (8.4 hrs) | B12: =B11*$B$28 | C12: =C11*$B$28 | D12: =D11*$B$28 | E12: =E11*$B$28 | F12: =F11*$B$28 | G12: =G11*$B$28 | H12: =H11*$B$28 | I12: =I11*$B$28 | ... K12: =K11*$B$28
A13: Years of City Service | B13: =YEAR(B$4)-YEAR($B$25)-IF(OR(MONTH(B$4)<MONTH($B$25),AND(MONTH(B$4)=MONTH($B$25),DAY(B$4)<DAY($B$25))),1,0) | C13: =YEAR(C$4)-YEAR($B$25)-IF(OR(MONTH(C$4)<MONTH($B$25),AND(MONTH(C$4)=MONTH($B$25),DAY(C$4)<DAY($B$25))),1,0) | D13: =YEAR(D$4)-YEAR($B$25)-IF(OR(MONTH(D$4)<MONTH($B$25),AND(MONTH(D$4)=MONTH($B$25),DAY(D$4)<DAY($B$25))),1,0) | E13: =YEAR(E$4)-YEAR($B$25)-IF(OR(MONTH(E$4)<MONTH($B$25),AND(MONTH(E$4)=MONTH($B$25),DAY(E$4)<DAY($B$25))),1,0) | F13: =YEAR(F$4)-YEAR($B$25)-IF(OR(MONTH(F$4)<MONTH($B$25),AND(MONTH(F$4)=MONTH($B$25),DAY(F$4)<DAY($B$25))),1,0) | G13: =YEAR(G$4)-YEAR($B$25)-IF(OR(MONTH(G$4)<MONTH($B$25),AND(MONTH(G$4)=MONTH($B$25),DAY(G$4)<DAY($B$25))),1,0) | H13: =YEAR(H$4)-YEAR($B$25)-IF(OR(MONTH(H$4)<MONTH($B$25),AND(MONTH(H$4)=MONTH($B$25),DAY(H$4)<DAY($B$25))),1,0) | I13: =YEAR(I$4)-YEAR($B$25)-IF(OR(MONTH(I$4)<MONTH($B$25),AND(MONTH(I$4)=MONTH($B$25),DAY(I$4)<DAY($B$25))),1,0) | ... K13: =YEAR(K$4)-YEAR($B$25)-IF(OR(MONTH(K$4)<MONTH($B$25),AND(MONTH(K$4)=MONTH($B$25),DAY(K$4)<DAY($B$25))),1,0)
A14: Longevity % (award schedule from 01/01/2026) | B14: =IF(B$4>=$B$38,VLOOKUP(B13,$A$41:$C$48,3,TRUE),VLOOKUP(B13,$A$41:$B$48,2,TRUE)) | C14: =IF(C$4>=$B$38,VLOOKUP(C13,$A$41:$C$48,3,TRUE),VLOOKUP(C13,$A$41:$B$48,2,TRUE)) | D14: =IF(D$4>=$B$38,VLOOKUP(D13,$A$41:$C$48,3,TRUE),VLOOKUP(D13,$A$41:$B$48,2,TRUE)) | E14: =IF(E$4>=$B$38,VLOOKUP(E13,$A$41:$C$48,3,TRUE),VLOOKUP(E13,$A$41:$B$48,2,TRUE)) | F14: =IF(F$4>=$B$38,VLOOKUP(F13,$A$41:$C$48,3,TRUE),VLOOKUP(F13,$A$41:$B$48,2,TRUE)) | G14: =IF(G$4>=$B$38,VLOOKUP(G13,$A$41:$C$48,3,TRUE),VLOOKUP(G13,$A$41:$B$48,2,TRUE)) | H14: =IF(H$4>=$B$38,VLOOKUP(H13,$A$41:$C$48,3,TRUE),VLOOKUP(H13,$A$41:$B$48,2,TRUE)) | I14: =IF(I$4>=$B$38,VLOOKUP(I13,$A$41:$C$48,3,TRUE),VLOOKUP(I13,$A$41:$B$48,2,TRUE)) | ... K14: =IF(K$4>=$B$38,VLOOKUP(K13,$A$41:$C$48,3,TRUE),VLOOKUP(K13,$A$41:$B$48,2,TRUE))
A15: Bi-Weekly Longevity | B15: =(B10+B12)*B14 | C15: =(C10+C12)*C14 | D15: =(D10+D12)*D14 | E15: =(E10+E12)*E14 | F15: =(F10+F12)*F14 | G15: =(G10+G12)*G14 | H15: =(H10+H12)*H14 | I15: =(I10+I12)*I14 | ... K15: =(K10+K12)*K14
A16: Total Bi-Weekly Pay (Base + Prem + Long) | B16: =B10+B12+B15 | C16: =C10+C12+C15 | D16: =D10+D12+D15 | E16: =E10+E12+E15 | F16: =F10+F12+F15 | G16: =G10+G12+G15 | H16: =H10+H12+H15 | I16: =I10+I12+I15 | ... K16: =K10+K12+K15
A17: Total Annual Pay | B17: =B16*$B$32 | C17: =C16*$B$32 | D17: =D16*$B$32 | E17: =E16*$B$32 | F17: =F16*$B$32 | G17: =G16*$B$32 | H17: =H16*$B$32 | I17: =I16*$B$32 | ... K17: =K16*$B$32
A18: OT Rate (12 hrs, incl. longevity) | B18: =B11*$B$30*$B$31*(1+B14) | C18: =C11*$B$30*$B$31*(1+C14) | D18: =D11*$B$30*$B$31*(1+D14) | E18: =E11*$B$30*$B$31*(1+E14) | F18: =F11*$B$30*$B$31*(1+F14) | G18: =G11*$B$30*$B$31*(1+G14) | H18: =H11*$B$30*$B$31*(1+H14) | I18: =I11*$B$30*$B$31*(1+I14) | ... K18: =K11*$B$30*$B$31*(1+K14)
A20: Total Annual WITHOUT the award (old sheet) | B20: =(B6/$B$26*$B$27+B6/$B$29*$B$28)*(1+VLOOKUP(B13,$A$41:$B$48,2,TRUE))*$B$32 | C20: =(C6/$B$26*$B$27+C6/$B$29*$B$28)*(1+VLOOKUP(C13,$A$41:$B$48,2,TRUE))*$B$32 | D20: =(D6/$B$26*$B$27+D6/$B$29*$B$28)*(1+VLOOKUP(D13,$A$41:$B$48,2,TRUE))*$B$32 | E20: =(E6/$B$26*$B$27+E6/$B$29*$B$28)*(1+VLOOKUP(E13,$A$41:$B$48,2,TRUE))*$B$32 | F20: =(F6/$B$26*$B$27+F6/$B$29*$B$28)*(1+VLOOKUP(F13,$A$41:$B$48,2,TRUE))*$B$32 | G20: =(G6/$B$26*$B$27+G6/$B$29*$B$28)*(1+VLOOKUP(G13,$A$41:$B$48,2,TRUE))*$B$32 | H20: =(H6/$B$26*$B$27+H6/$B$29*$B$28)*(1+VLOOKUP(H13,$A$41:$B$48,2,TRUE))*$B$32 | I20: =(I6/$B$26*$B$27+I6/$B$29*$B$28)*(1+VLOOKUP(I13,$A$41:$B$48,2,TRUE))*$B$32 | ... K20: =(K6/$B$26*$B$27+K6/$B$29*$B$28)*(1+VLOOKUP(K13,$A$41:$B$48,2,TRUE))*$B$32
A21: Annual Increase from the Award | B21: =B17-B20 | C21: =C17-C20 | D21: =D17-D20 | E21: =E17-E20 | F21: =F17-F20 | G21: =G17-G20 | H21: =H17-H20 | I21: =I17-I20 | ... K21: =K17-K20
A24: INPUTS & ASSUMPTIONS — edit the blue and yellow cells
A25: City employment start date (sets longevity) | B25: 45022 | C25: ASSUMED from the Step 1 date on the original sheet — replace with your real hire date.
A26: Annual hours (base pay divisor) | B26: 2192 | C26: From the original sheet.
A27: Regular hours per check | B27: 84
A28: Premium hours per check | B28: 8.4 | C28: 8 hrs x 1.05 fire premium.
A29: Premium/OT hours divisor | B29: 2088 | C29: From the original sheet.
A30: OT multiplier | B30: 1.5
A31: OT hours priced in the OT row | B31: 12
A32: Paychecks per year | B32: 26
A34: Act 111 Award raises | B34: Effective | C34: Raise
A35: First raise | B35: 45839 | C35: 0.03 | D35: Compounded, not added: 3% then 1% then 3% = 7.1509% total.
A36: Second raise | B36: 46023 | C36: 0.01
A37: Third raise | B37: 46204 | C37: 0.03
A38: Award longevity schedule effective | B38: 46023 | C38: Before this date the old longevity percentages apply.
A40: Years of service | B40: Old longevity % | C40: Award longevity % | D40: Longevity is paid on base + fire premium.
A41: 0 | B41: 0 | C41: 0
A42: 3 | B42: 0.033 | C42: 0.043
A43: 5 | B43: 0.038 | C43: 0.048
A44: 10 | B44: 0.045 | C44: 0.055
A45: 15 | B45: 0.052 | C45: 0.062
...

Sheet All Ranks - Award Scale
A1: Every rank and step, before and after the Act 111 Award
A2: Base salary only (no premium, no longevity). Award column = pre-award salary x 1.071509, except the paramedic-series ranks, which move to their own negotiated award scale on 07/01/2026.
A4: Rank | B4: Scale | C4: Step 1 | D4: Step 2 | E4: Step 3 | F4: Step 4 | G4: Step 5 | H4: Step 6 | I4: Notes
A5: FIREFIGHTER | B5: Pre-award | C5: 64982 | D5: 69492 | E5: 75814 | F5: 81227 | G5: 86643 | H5: 90253
B6: With award | C6: =C5*(1+'Pay Scale'!$C$35)*(1+'Pay Scale'!$C$36)*(1+'Pay Scale'!$C$37) | D6: =D5*(1+'Pay Scale'!$C$35)*(1+'Pay Scale'!$C$36)*(1+'Pay Scale'!$C$37) | E6: =E5*(1+'Pay Scale'!$C$35)*(1+'Pay Scale'!$C$36)*(1+'Pay Scale'!$C$37) | F6: =F5*(1+'Pay Scale'!$C$35)*(1+'Pay Scale'!$C$36)*(1+'Pay Scale'!$C$37) | G6: =G5*(1+'Pay Scale'!$C$35)*(1+'Pay Scale'!$C$36)*(1+'Pay Scale'!$C$37) | H6: =H5*(1+'Pay Scale'!$C$35)*(1+'Pay Scale'!$C$36)*(1+'Pay Scale'!$C$37)
A7: EMERGENCY MEDICAL TECH | B7: Pre-award | C7: 54155 | D7: 57911 | E7: 63177 | F7: 67687 | G7: 72203 | H7: 75212
B8: With award | C8: =C7*(1+'Pay Scale'!$C$35)*(1+'Pay Scale'!$C$36)*(1+'Pay Scale'!$C$37) | D8: =D7*(1+'Pay Scale'!$C$35)*(1+'Pay Scale'!$C$36)*(1+'Pay Scale'!$C$37) | E8: =E7*(1+'Pay Scale'!$C$35)*(1+'Pay Scale'!$C$36)*(1+'Pay Scale'!$C$37) | F8: =F7*(1+'Pay Scale'!$C$35)*(1+'Pay Scale'!$C$36)*(1+'Pay Scale'!$C$37) | G8: =G7*(1+'Pay Scale'!$C$35)*(1+'Pay Scale'!$C$36)*(1+'Pay Scale'!$C$37) | H8: =H7*(1+'Pay Scale'!$C$35)*(1+'Pay Scale'!$C$36)*(1+'Pay Scale'!$C$37)
A9: FIRE SERV PARAMEDIC | B9: Pre-award | C9: 64982 | D9: 76441 | E9: 83396 | F9: 89350 | G9: 95309 | H9: 99276
B10: With award | C10: 72285 | D10: 85033 | E10: 92770 | F10: 99393 | G10: 106021 | H10: 110434 | I10: Paramedic-series award scale, effective 07/01/2026.
A11: FIRE BOAT ENGINEER | B11: Pre-award | D11: 76441 | E11: 83396 | F11: 89350 | G11: 95305 | H11: 99278
B12: With award | D12: =D11*(1+'Pay Scale'!$C$35)*(1+'Pay Scale'!$C$36)*(1+'Pay Scale'!$C$37) | E12: =E11*(1+'Pay Scale'!$C$35)*(1+'Pay Scale'!$C$36)*(1+'Pay Scale'!$C$37) | F12: =F11*(1+'Pay Scale'!$C$35)*(1+'Pay Scale'!$C$36)*(1+'Pay Scale'!$C$37) | G12: =G11*(1+'Pay Scale'!$C$35)*(1+'Pay Scale'!$C$36)*(1+'Pay Scale'!$C$37) | H12: =H11*(1+'Pay Scale'!$C$35)*(1+'Pay Scale'!$C$36)*(1+'Pay Scale'!$C$37)
A13: FIRE BOAT PILOT | B13: Pre-award | D13: 97747 | E13: 99859 | F13: 101985
B14: With award | D14: =D13*(1+'Pay Scale'!$C$35)*(1+'Pay Scale'!$C$36)*(1+'Pay Scale'!$C$37) | E14: =E13*(1+'Pay Scale'!$C$35)*(1+'Pay Scale'!$C$36)*(1+'Pay Scale'!$C$37) | F14: =F13*(1+'Pay Scale'!$C$35)*(1+'Pay Scale'!$C$36)*(1+'Pay Scale'!$C$37)
A15: FIRE LIEUTENANT | B15: Pre-award | D15: 98611 | E15: 100744 | F15: 102887
B16: With award | D16: =D15*(1+'Pay Scale'!$C$35)*(1+'Pay Scale'!$C$36)*(1+'Pay Scale'!$C$37) | E16: =E15*(1+'Pay Scale'!$C$35)*(1+'Pay Scale'!$C$36)*(1+'Pay Scale'!$C$37) | F16: =F15*(1+'Pay Scale'!$C$35)*(1+'Pay Scale'!$C$36)*(1+'Pay Scale'!$C$37)
A17: FIRE PARA LIEUT | B17: Pre-award | D17: 98611 | E17: 100744 | F17: 102887
B18: With award | D18: 109695 | E18: 112067 | F18: 114452 | I18: Paramedic-series award scale, effective 07/01/2026.
A19: FIRE CAPTAIN | B19: Pre-award | D19: 112417 | E19: 114849 | F19: 117290
B20: With award | D20: =D19*(1+'Pay Scale'!$C$35)*(1+'Pay Scale'!$C$36)*(1+'Pay Scale'!$C$37) | E20: =E19*(1+'Pay Scale'!$C$35)*(1+'Pay Scale'!$C$36)*(1+'Pay Scale'!$C$37) | F20: =F19*(1+'Pay Scale'!$C$35)*(1+'Pay Scale'!$C$36)*(1+'Pay Scale'!$C$37)
A21: FIRE PARA CAPT | B21: Pre-award | D21: 112417 | E21: 114849 | F21: 117290
B22: With award | D22: 122858 | E22: 125515 | F22: 128186 | I22: Paramedic-series award scale, effective 07/01/2026.
A23: FSP INFECTION CONTROL OFF. | B23: Pre-award | D23: 112417 | E23: 114849 | F23: 117290
B24: With award | D24: =D23*(1+'Pay Scale'!$C$35)*(1+'Pay Scale'!$C$36)*(1+'Pay Scale'!$C$37) | E24: =E23*(1+'Pay Scale'!$C$35)*(1+'Pay Scale'!$C$36)*(1+'Pay Scale'!$C$37) | F24: =F23*(1+'Pay Scale'!$C$35)*(1+'Pay Scale'!$C$36)*(1+'Pay Scale'!$C$37)
A25: FIRE BATTALION CHIEF | B25: Pre-award | D25: 130405 | E25: 133226 | F25: 136058
B26: With award | D26: =D25*(1+'Pay Scale'!$C$35)*(1+'Pay Scale'!$C$36)*(1+'Pay Scale'!$C$37) | E26: =E25*(1+'Pay Scale'!$C$35)*(1+'Pay Scale'!$C$36)*(1+'Pay Scale'!$C$37) | F26: =F25*(1+'Pay Scale'!$C$35)*(1+'Pay Scale'!$C$36)*(1+'Pay Scale'!$C$37)
A27: FIRE PARA BATTALION CHIEF | B27: Pre-award | D27: 130405 | E27: 133226 | F27: 136058
B28: With award | D28: 138830 | E28: 141832 | F28: 144850 | I28: Paramedic-series award scale, effective 07/01/2026.
A29: FIRE DEPUTY CHIEF | B29: Pre-award | D29: 148660 | E29: 151875 | F29: 155106
B30: With award | D30: =D29*(1+'Pay Scale'!$C$35)*(1+'Pay Scale'!$C$36)*(1+'Pay Scale'!$C$37) | E30: =E29*(1+'Pay Scale'!$C$35)*(1+'Pay Scale'!$C$36)*(1+'Pay Scale'!$C$37) | F30: =F29*(1+'Pay Scale'!$C$35)*(1+'Pay Scale'!$C$36)*(1+'Pay Scale'!$C$37)
A31: FIRE PARA DEPUTY CHIEF | B31: Pre-award | D31: 148660 | E31: 151875 | F31: 155106
B32: With award | D32: 158266 | E32: 161688 | F32: 165130 | I32: Paramedic-series award scale, effective 07/01/2026.
A33: ASSISTANT FIRE CHIEF | B33: Pre-award | D33: 169474 | E33: 173139 | F33: 176820
B34: With award | D34: =D33*(1+'Pay Scale'!$C$35)*(1+'Pay Scale'!$C$36)*(1+'Pay Scale'!$C$37) | E34: =E33*(1+'Pay Scale'!$C$35)*(1+'Pay Scale'!$C$36)*(1+'Pay Scale'!$C$37) | F34: =F33*(1+'Pay Scale'!$C$35)*(1+'Pay Scale'!$C$36)*(1+'Pay Scale'!$C$37)
A36: Award factor 1.071509 = 1.03 x 1.01 x 1.03 (compounded).
A37: Source: IAFF Local 22 - City of Philadelphia Act 111 Award, June 26, 2026, paragraphs 2-5.
A38: Base salary before premium, longevity and overtime.
